<?xml version="1.0"?>

<robot name="myroboticarm">

<!-- base link:fixed-->
    <link name="world"/>
    <link name="base_link">
        <visual>
          <geometry>
            <cylinder radius="0.3" length="0.05"/>
          </geometry>
          <material name="Black"/>
          <origin xyz="0 0 0.025" rpy="0 0 0"/>
        </visual>    
        <collision>
          <geometry>
            <cylinder radius="0.3" length="0.05"/>
          </geometry>
        </collision>
        <inertial>
          <mass value="1"/>
          <origin xyz="0 0 0"/>
          <inertia ixx="0.0027" iyy="0.0025" izz="0.005" ixy="0.0" ixz="0.0" iyz="0.0"/>
        </inertial>
    </link>

    <joint name="world_to_base" type="fixed">
        <parent link="world"/>
        <child link="base_link"/>
    </joint>

<!--one -->
    <link name="one">
        <visual>
          <geometry>
            <cylinder radius="0.05" length="0.5"/>
          </geometry>
          <material name="Silver">
            <color rgba="0.75 0.75 0.75 1.0"/>
          </material>  
          <origin xyz="0 0 0.25" rpy="0 0 0"/>
        </visual>    
        <collision>
          <geometry>
            <cylinder radius="0.05" length="0.5"/>
          </geometry>
        </collision>
        <inertial>
          <mass value="1"/>
          <origin xyz="0 0 0.25"/>
          <inertia ixx="0.002176" iyy="0.0215" izz="0.00125" ixy="0.0" ixz="0.0" iyz="0.0"/>
        </inertial>
    </link>

    <joint name="base_to_one" type="continuous">
        <parent link="base_link"/>
        <child link="one"/>
        <axis xyz="0 0 1"/>
        <origin xyz="0 0 0.05" rpy="0 0 0.0"/>
    </joint>

<!-- elbow joint-->

    <link name="two">
        <visual>
          <geometry>
            <cylinder radius="0.05" length="0.5"/>
          </geometry>
          <material name="Silver">
            <color rgba="0.75 0.75 0.75 1.0"/>
          </material>  
          <origin xyz="0 0 0.25" rpy="0 0 0"/>
        </visual>    
        <collision>
          <geometry>
            <cylinder radius="0.05" length="0.5"/>
          </geometry>
        </collision>
        <inertial>
          <mass value="1"/>
          <origin xyz="0 0 0.25"/>
          <inertia ixx="0.01396" iyy="0.0015" izz="0.01396" ixy="0.0" ixz="0.0" iyz="0.0"/>
        </inertial>
    </link>

    <joint name="one_to_elbow" type="continuous">
        <parent link="one"/>
        <child link="two"/>
        <axis xyz="0 0 1"/>
        <origin xyz="0 0 0.55" rpy="0 1.5708 0.0"/>
    </joint>

<!-- third-->

    <link name="three">
        <visual>
          <geometry>
            <cylinder radius="0.05" length="0.3"/>
          </geometry>
          <material name="Silver">
            <color rgba="0.75 0.75 0.75 1.0"/>
          </material>  
          <origin xyz="0 0 0.15" rpy="0 0 0"/>
        </visual>    
        <collision>
          <geometry>
            <cylinder radius="0.05" length="0.3"/>
          </geometry>
        </collision>
        <inertial>
          <mass value="1"/>
          <origin xyz="0 0 0.25"/>
          <inertia ixx="0.01396" iyy="0.0015" izz="0.01396" ixy="0.0" ixz="0.0" iyz="0.0"/>
        </inertial>
    </link>

    <joint name="two_to_three" type="continuous">
        <parent link="two"/>
        <child link="three"/>
        <axis xyz="0 0 1"/>
        <origin xyz="0. 0 0.55" rpy="0 -1.5708 0.0"/>
    </joint>

<!-- fourth-->

    <link name="four">
        <visual>
          <geometry>
            <cylinder radius="0.05" length="0.5"/>
          </geometry>
          <material name="Silver">
            <color rgba="0.75 0.75 0.75 1.0"/>
          </material>  
          <origin xyz="0 0 0.25" rpy="0 0 0"/>
        </visual>    
        <collision>
          <geometry>
            <cylinder radius="0.05" length="0.5"/>
          </geometry>
        </collision>
        <inertial>
          <mass value="1"/>
          <origin xyz="0 0 0.25"/>
          <inertia ixx="0.01396" iyy="0.0015" izz="0.01396" ixy="0.0" ixz="0.0" iyz="0.0"/>
        </inertial>
    </link>

    <joint name="three_to_four" type="continuous">
        <parent link="three"/>
        <child link="four"/>
        <axis xyz="0 0 1"/>
        <origin xyz="0. 0 0.3" rpy="0 1.5708 0.0"/>
    </joint>

<!-- gripper base-->   

    <link name="gripper_base">
        <visual>
          <geometry>
            <cylinder radius="0.08" length="0.02"/>
          </geometry>
          <material name="Silver">
            <color rgba="0.75 0.75 0.75 1.0"/>
          </material>  
          <origin xyz="0 0 0.01" rpy="0 0 0"/>
        </visual>    
        <collision>
          <geometry>
            <cylinder radius="0.08" length="0.1"/>
          </geometry>
        </collision>
        <inertial>
          <mass value="1"/>
          <origin xyz="0 0 0.25"/>
          <inertia ixx="0.01396" iyy="0.0015" izz="0.01396" ixy="0.0" ixz="0.0" iyz="0.0"/>
        </inertial>
    </link>

    <joint name="four_to_gripper" type="continuous">
        <parent link="four"/>
        <child link="gripper_base"/>
        <axis xyz="0 0 1"/>
        <origin xyz="0 0 0.5" rpy="0 0 0.0"/>
    </joint>

<!-- left finger-->

<link name="left_finger">
        <visual>
          <geometry>
            <box size="0.02 0.02 0.15"/>
          </geometry>
          <material name="Black"/>
          <origin xyz="0 0 0.075" rpy="0 0 0"/>
        </visual>    
        <collision>
          <geometry>
            <box size="0.02 0.02 0.15"/>
          </geometry>
        </collision>
        <inertial>
          <mass value="1"/>
          <origin xyz="0 0 0.25"/>
          <inertia ixx="100" iyy="100" izz="0.01396" ixy="0.0" ixz="0.0" iyz="0.0"/>
        </inertial>
    </link>

    <joint name="left_finger_to_gripper_base" type="prismatic">
        <limit lower="-0.02" upper="0.02" effort="100" velocity="1.0"/>
        <parent link="gripper_base"/>
        <child link="left_finger"/>
        <axis xyz="0 1 0"/>
        <origin xyz="0 0.04 0.02" rpy="0 0 0.0"/>
    </joint>

<!-- right finger--> 

<link name="right_finger">
        <visual>
          <geometry>
            <box size="0.02 0.02 0.15"/>
          </geometry>
          <material name="Black"/>
          <origin xyz="0 0 0.075" rpy="0 0 0"/>
        </visual>    
        <collision>
          <geometry>
            <box size="0.02 0.02 0.15"/>
          </geometry>
        </collision>
        <inertial>
          <mass value="1"/>
          <origin xyz="0 0 0.25"/>
          <inertia ixx="100" iyy="100" izz="0.01396" ixy="0.0" ixz="0.0" iyz="0.0"/>
        </inertial>
    </link>

    <joint name="right_finger_to_gripper_base" type="prismatic">
        <limit lower="0.02" upper="-0.02" effort="100" velocity="1.0"/>
        <parent link="gripper_base"/>
        <child link="right_finger"/>
        <axis xyz="0 1 0"/>
        <origin xyz="0 -0.04 0.02" rpy="0 0 0.0"/>
    </joint>












</robot>          
